<?xml version="1.0" ?>
<!-- Generated using onshape-to-robot -->
<!-- Onshape document_id: 3023829f8e4e5c564f6b4985 -->
<robot xmlns:xacro="http://www.ros.org/wiki/xacro">


  <!-- Link base footprint -->
  <link name="base_footprint"/>
  <!-- Joint base footprint -->
  <joint name="base_joint" type="fixed">
      <parent link="base_footprint" />
      <child link="base_link" />
      <origin xyz="0 0 0.0158450026" rpy="0 0 0" />
  </joint>

  <!-- Link base_t -->
  <link name="base_link">
    <inertial>
      <origin xyz="0.0112256 -0 0.0778907" rpy="0 0 0"/>
      <mass value="4.81654"/>
      <inertia ixx="0.0259231" ixy="0" ixz="-0.00401137" iyy="0.0296606" iyz="0" izz="0.0400591"/>
    </inertial>
    <!-- Part base_t -->
    <visual>
      <origin xyz="0 0 0" rpy="0 -0 0"/>
      <geometry>
        <mesh filename="package://my_robot_description/assets/base_t.stl"/>
      </geometry>
      <material name="base_t_material">
        <color rgba="0.537255 0.854902 0.827451 1"/>
      </material>
    </visual>
    <collision>
      <origin xyz="0 0 0" rpy="0 -0 0"/>
      <geometry>
        <mesh filename="package://my_robot_description/assets/base_t.stl"/>
      </geometry>
    </collision>
  </link>
  <!-- Link llanta_dere_del -->
  <link name="llanta_dere_del_link">
    <inertial>
      <origin xyz="0 -0 -0.0264625" rpy="0 0 0"/>
      <mass value="0.0901579"/>
      <inertia ixx="2.81915e-05" ixy="0" ixz="0" iyy="2.83576e-05" iyz="0" izz="4.79296e-05"/>
    </inertial>
    <!-- Part llanta_dere_del -->
    <visual>
      <origin xyz="0 0 -0.015" rpy="1.5708 -0 0"/>
      <geometry>
        <mesh filename="package://my_robot_description/assets/llanta_dere_del.stl"/>
      </geometry>
      <material name="llanta_dere_del_material">
        <color rgba="0.980392 0.713725 0.00392157 1"/>
      </material>
    </visual>
    <collision>
      <origin xyz="0 0 -0.015" rpy="1.5708 -0 0"/>
      <geometry>
        <mesh filename="package://my_robot_description/assets/llanta_dere_del.stl"/>
      </geometry>
    </collision>
  </link>
  <!-- Joint from base_t to llanta_dere_del -->
  <joint name="llanta_dere_del_joint" type="continuous">
    <origin xyz="0.0441 -0.095 0.0162" rpy="-1.5708 -0 0"/>
    <parent link="base_link"/>
    <child link="llanta_dere_del_link"/>
    <axis xyz="0 0 1"/>
    <limit effort="100" velocity="100"/>
  </joint>
  <!-- Link llanta_dere_tra -->
  <link name="llanta_dere_tra_link">
    <inertial>
      <origin xyz="-0 -0 -0.0264625" rpy="0 0 0"/>
      <mass value="0.0901579"/>
      <inertia ixx="2.81915e-05" ixy="0" ixz="0" iyy="2.83576e-05" iyz="0" izz="4.79296e-05"/>
    </inertial>
    <!-- Part llanta_dere_tra -->
    <visual>
      <origin xyz="-0 0 -0.015" rpy="1.5708 -0 0"/>
      <geometry>
        <mesh filename="package://my_robot_description/assets/llanta_dere_tra.stl"/>
      </geometry>
      <material name="llanta_dere_tra_material">
        <color rgba="0.980392 0.713725 0.00392157 1"/>
      </material>
    </visual>
    <collision>
      <origin xyz="-0 0 -0.015" rpy="1.5708 -0 0"/>
      <geometry>
        <mesh filename="package://my_robot_description/assets/llanta_dere_tra.stl"/>
      </geometry>
    </collision>
  </link>
  <!-- Joint from base_t to llanta_dere_tra -->
  <joint name="llanta_dere_tra_joint" type="continuous">
    <origin xyz="-0.0859 -0.095 0.0162" rpy="-1.5708 -0 0"/>
    <parent link="base_link"/>
    <child link="llanta_dere_tra_link"/>
    <axis xyz="0 0 1"/>
    <limit effort="100" velocity="100"/>
  </joint>
  <!-- Link llanta_iz_del -->
  <link name="llanta_iz_del_link">
    <inertial>
      <origin xyz="-0 0 -0.0264625" rpy="0 0 0"/>
      <mass value="0.0901579"/>
      <inertia ixx="2.81477e-05" ixy="0" ixz="0" iyy="2.84014e-05" iyz="0" izz="4.79296e-05"/>
    </inertial>
    <!-- Part llanta_iz_del -->
    <visual>
      <origin xyz="-0 0 -0.04169" rpy="-1.5708 -0 0"/>
      <geometry>
        <mesh filename="package://my_robot_description/assets/llanta_iz_del.stl"/>
      </geometry>
      <material name="llanta_iz_del_material">
        <color rgba="0.980392 0.713725 0.00392157 1"/>
      </material>
    </visual>
    <collision>
      <origin xyz="-0 0 -0.04169" rpy="-1.5708 -0 0"/>
      <geometry>
        <mesh filename="package://my_robot_description/assets/llanta_iz_del.stl"/>
      </geometry>
    </collision>
  </link>
  <!-- Joint from base_t to llanta_iz_del -->
  <joint name="llanta_iz_del_joint" type="continuous">
    <origin xyz="0.0441 0.095 0.0162" rpy="1.5708 -0 0"/>
    <parent link="base_link"/>
    <child link="llanta_iz_del_link"/>
    <axis xyz="0 0 -1"/>
    <limit effort="100" velocity="100"/>
  </joint>
  <!-- Link llanta_iz_tra -->
  <link name="llanta_iz_tra_link">
    <inertial>
      <origin xyz="0 0 -0.0264625" rpy="0 0 0"/>
      <mass value="0.0901579"/>
      <inertia ixx="2.81477e-05" ixy="0" ixz="0" iyy="2.84014e-05" iyz="0" izz="4.79296e-05"/>
    </inertial>
    <!-- Part llanta_iz_tra -->
    <visual>
      <origin xyz="0 0 -0.04169" rpy="-1.5708 -0 0"/>
      <geometry>
        <mesh filename="package://my_robot_description/assets/llanta_iz_tra.stl"/>
      </geometry>
      <material name="llanta_iz_tra_material">
        <color rgba="0.980392 0.713725 0.00392157 1"/>
      </material>
    </visual>
    <collision>
      <origin xyz="0 0 -0.04169" rpy="-1.5708 -0 0"/>
      <geometry>
        <mesh filename="package://my_robot_description/assets/llanta_iz_tra.stl"/>
      </geometry>
    </collision>
  </link>
  <!-- Joint from base_t to llanta_iz_tra -->
  <joint name="llanta_iz_tra_joint" type="continuous">
    <origin xyz="-0.0859 0.095 0.0162" rpy="1.5708 -0 0"/>
    <parent link="base_link"/>
    <child link="llanta_iz_tra_link"/>
    <axis xyz="0 0 -1"/>
    <limit effort="100" velocity="100"/>
  </joint>

</robot>  